# 错误处理

## 错误处理概述

Rust 的可靠性：错误处理

- 大部分情况下：在编译时提示错误，并处理
- 错误的分类：
    - 可恢复，例如 文件未找到，可再次尝试
    - 不可恢复，bug，例如 访问的索引超出范围

Rust 没有类似异常的机制

- 可恢复错误：`Result<T，E>`
- 不可恢复：`panic!` 宏

## panic!

处理不可恢复的错误

当 `panic!` 宏执行：

- 你的程序会打印一个错误信息
- 展开（unwind）、清理调用栈（Stack）
- 退出程序

**为应对 panic，展开或中止（abort）调用栈**

1. 默认情况下，当 panic 发生：

- 程序展开调用栈（工作量大）

- Rust 沿着调用栈往回走

- 清理每个遇到的函数中的数据

2. 或立即中止调用栈:

- 不进行清理，直接停止程序

- 内存需要 OS 进行清理

想让二进制文件更小，把设置从“展开”改为“中止”：

在 Cargo.toml 中适当的 profile 部分设置：`panic = 'abort'`

**使用 panic! 产生的回溯信息**

panic! 可能出现在：

- 我们写的代码中

- 我们所依赖的代码中

可通过调用 `panic!` 的函数的回溯信息来定位引起问题的代码

通过设置环境变量 `RUST_BACKTRACE` 可得到回溯信息：`set RUST_BACKTRACE=1`

## Result 与可恢复的错误

**Result 枚举**

```rust
enum Result<T, E> {
	Ok(T),
	Err(E),
}
```

T：操作成功情况下，Ok 变体里返回的数据的类型

E：操作失败情况下，Err 变体里返回的错误的类型

**处理 Result 的一种方式：match 表达式**

和 Option 枚举一样，Result 及其变体也是由 prelude 带入作用域

```rust
use std::fs::File;

fn main() {
    let greeting_file_result = File::open("hello.txt");

    let greeting_file = match greeting_file_result {
        Ok(file) => file,
        Err(error) => panic!("Problem opening the file: {:?}", error),
    };
}
```

**匹配不同的错误**

```rust
use std::fs::File;
use std::io::ErrorKind;

fn main() {
    let greeting_file_result = File::open("hello.txt");

    let greeting_file = match greeting_file_result {
        Ok(file) => file,
        Err(error) => match error.kind() {
            ErrorKind::NotFound => match File::create("hello.txt") {
                Ok(fc) => fc,
                Err(e) => panic!("Problem creating the file: {:?}", e),
            },
            other_error => {
                panic!("Problem opening the file: {:?}", other_error);
            }
        },
    };
}
```

上例中使用了很多 match，match 很有用，但是很原始，後面會講闭包（closure）。`Result<T，E>`有很多方法

- 它们接收闭包作为参数
- 使用match实现
- 使用这些方法会让代码更简洁

For example, here’s another way to write the same logic as shown in Listing 9-5, this time using closures and the `unwrap_or_else` method:

```rust
use std::fs::File;
use std::io::ErrorKind;

fn main() {
    let greeting_file = File::open("hello.txt").unwrap_or_else(|error| {
        if error.kind() == ErrorKind::NotFound {
            File::create("hello.txt").unwrap_or_else(|error| {
                panic!("Problem creating the file: {:?}", error);
            })
        } else {
            panic!("Problem opening the file: {:?}", error);
        }
    });
}
```

Although this code has the same behavior as Listing 9-5, it doesn’t contain any `match` expressions and is cleaner to read 😒. Come back to this example after you’ve read Chapter 13, and look up the `unwrap_or_else` method in the standard library documentation. Many more of these methods can clean up huge nested `match` expressions when you’re dealing with errors.

## Shortcuts for Panic on Error

`unwrap`：match 表达式的一个快捷方法

- 如果 Result 结果是 Ok，返回 Ok 里面的值

- 如果 Result 结果是 Err，调用 panic! 宏

Here is an example of `unwrap` in action:

```rust
use std::fs::File;

fn main() {
    let greeting_file = File::open("hello.txt").unwrap();
}
```

`expect`：和 unwrap 类似，但可指定错误信息

```rust
use std::fs::File;

fn main() {
    let greeting_file = File::open("hello.txt")
        .expect("hello.txt should be included in this project");
}
```

We use `expect` in the same way as `unwrap`: to return the file handle or call the `panic!` macro. The error message used by `expect` in its call to `panic!` will be the parameter that we pass to `expect`, rather than the default `panic!` message that `unwrap` uses.

**传播错误**

- 在函数中处理错误
- 将错误返回给调用者

代碼實例：

```rust
#![allow(unused)]
use std::fs::File;
use std::io::{self, Read};

fn read_username_from_file() -> Result<String, io::Error> { // 把err傳出去
    let username_file_result = File::open("hello.txt");

    let mut username_file = match username_file_result {
        Ok(file) => file,
        Err(e) => return Err(e),
    };

    let mut username = String::new();

    match username_file.read_to_string(&mut username) {
        Ok(_) => Ok(username),
        Err(e) => Err(e),
    }
}
```

**A Shortcut for Propagating Errors: the `?` Operator**

? 运算符：传播错误的一种快捷方式

- 如果 Result 是 Ok：Ok 中的值就是表达式的结果，然后继续执行程序

- 如果 Result 是 Err：Err 就是**整个函数**的返回值，就像使用了 return

使用 ? 簡化上述程序：

```rust
#![allow(unused)]
use std::fs::File;
use std::io;
use std::io::Read;

fn read_username_from_file() -> Result<String, io::Error> {
    let mut username_file = File::open("hello.txt")?;
    let mut username = String::new();
    username_file.read_to_string(&mut username)?;
    Ok(username)
}

fn read_username_from_file() -> Result<String, io::Error> {
    let mut username = String::new();
    File::open("hello.txt")?.read_to_string(&mut username)?;
    Ok(username)
}

fn read_username_from_file() -> Result<String, io::Error> {
    fs::read_to_string("hello.txt")
}
```

**? 运算符只能用于返回 Result 的函数**

例如：? 运算符与 main 函数，main 函数返回类型是：() 时是不对的

**总体原则**

- 在定义一个可能失败的函数时，优先考虑返回 Result
- 否则就 panic!